2012-05-28 23:18:02,914 Host resolution error: [Failure instance: Traceback (failure with no frames): <class 'twisted.internet.error.DNSLookupError'>: DNS lookup failed: address 'deoliokwfv' not found: [Errno -5] No address associated with hostname.
]
2012-05-28 23:18:02,920 Host resolution error: [Failure instance: Traceback (failure with no frames): <class 'twisted.internet.error.DNSLookupError'>: DNS lookup failed: address 'xfvmldqoee' not found: [Errno -5] No address associated with hostname.
]
2012-05-28 23:18:02,922 Host resolution error: [Failure instance: Traceback (failure with no frames): <class 'twisted.internet.error.DNSLookupError'>: DNS lookup failed: address 'gzbatjlzvg' not found: [Errno -5] No address associated with hostname.
]
2012-05-28 23:18:14,007 Host resolution error: [Failure instance: Traceback: <type 'exceptions.ValueError'>: I/O operation on closed file
/usr/lib/python2.7/dist-packages/twisted/internet/defer.py:542:_runCallbacks
/usr/lib/python2.7/dist-packages/twisted/internet/base.py:250:_checkTimeout
/usr/lib/python2.7/dist-packages/twisted/internet/defer.py:361:callback
/usr/lib/python2.7/dist-packages/twisted/internet/defer.py:455:_startRunCallbacks
--- <exception caught here> ---
/usr/lib/python2.7/dist-packages/twisted/internet/defer.py:542:_runCallbacks
/home/raul/Desktop/Dropbox/Lupin/Lupin/Lupin/ClientRequest.py:94:handleHostResolvedSuccess
]
2012-05-28 23:18:14,026 Host resolution error: [Failure instance: Traceback: <type 'exceptions.ValueError'>: I/O operation on closed file
/usr/lib/python2.7/dist-packages/twisted/internet/defer.py:542:_runCallbacks
/usr/lib/python2.7/dist-packages/twisted/internet/base.py:250:_checkTimeout
/usr/lib/python2.7/dist-packages/twisted/internet/defer.py:361:callback
/usr/lib/python2.7/dist-packages/twisted/internet/defer.py:455:_startRunCallbacks
--- <exception caught here> ---
/usr/lib/python2.7/dist-packages/twisted/internet/defer.py:542:_runCallbacks
/home/raul/Desktop/Dropbox/Lupin/Lupin/Lupin/ClientRequest.py:94:handleHostResolvedSuccess
]
2012-05-28 23:18:21,007 Host resolution error: [Failure instance: Traceback: <type 'exceptions.ValueError'>: I/O operation on closed file
/usr/lib/python2.7/dist-packages/twisted/internet/defer.py:542:_runCallbacks
/usr/lib/python2.7/dist-packages/twisted/internet/base.py:250:_checkTimeout
/usr/lib/python2.7/dist-packages/twisted/internet/defer.py:361:callback
/usr/lib/python2.7/dist-packages/twisted/internet/defer.py:455:_startRunCallbacks
--- <exception caught here> ---
/usr/lib/python2.7/dist-packages/twisted/internet/defer.py:542:_runCallbacks
/home/raul/Desktop/Dropbox/Lupin/Lupin/Lupin/ClientRequest.py:94:handleHostResolvedSuccess
]
2012-05-28 23:18:21,300 Host resolution error: [Failure instance: Traceback (failure with no frames): <class 'twisted.internet.error.DNSLookupError'>: DNS lookup failed: address 'www.kaskus.us' not found: [Errno -5] No address associated with hostname.
]
2012-05-28 23:18:28,007 Host resolution error: [Failure instance: Traceback: <type 'exceptions.ValueError'>: I/O operation on closed file
/usr/lib/python2.7/dist-packages/twisted/internet/defer.py:542:_runCallbacks
/usr/lib/python2.7/dist-packages/twisted/internet/base.py:250:_checkTimeout
/usr/lib/python2.7/dist-packages/twisted/internet/defer.py:361:callback
/usr/lib/python2.7/dist-packages/twisted/internet/defer.py:455:_startRunCallbacks
--- <exception caught here> ---
/usr/lib/python2.7/dist-packages/twisted/internet/defer.py:542:_runCallbacks
/home/raul/Desktop/Dropbox/Lupin/Lupin/Lupin/ClientRequest.py:94:handleHostResolvedSuccess
]
2012-05-28 23:18:28,017 Host resolution error: [Failure instance: Traceback: <type 'exceptions.ValueError'>: I/O operation on closed file
/usr/lib/python2.7/dist-packages/twisted/internet/defer.py:542:_runCallbacks
/usr/lib/python2.7/dist-packages/twisted/internet/base.py:250:_checkTimeout
/usr/lib/python2.7/dist-packages/twisted/internet/defer.py:361:callback
/usr/lib/python2.7/dist-packages/twisted/internet/defer.py:455:_startRunCallbacks
--- <exception caught here> ---
/usr/lib/python2.7/dist-packages/twisted/internet/defer.py:542:_runCallbacks
/home/raul/Desktop/Dropbox/Lupin/Lupin/Lupin/ClientRequest.py:94:handleHostResolvedSuccess
]
2012-05-28 23:18:28,982 Host resolution error: [Failure instance: Traceback: <type 'exceptions.ValueError'>: I/O operation on closed file
/usr/lib/python2.7/dist-packages/twisted/internet/defer.py:542:_runCallbacks
/usr/lib/python2.7/dist-packages/twisted/internet/base.py:250:_checkTimeout
/usr/lib/python2.7/dist-packages/twisted/internet/defer.py:361:callback
/usr/lib/python2.7/dist-packages/twisted/internet/defer.py:455:_startRunCallbacks
--- <exception caught here> ---
/usr/lib/python2.7/dist-packages/twisted/internet/defer.py:542:_runCallbacks
/home/raul/Desktop/Dropbox/Lupin/Lupin/Lupin/ClientRequest.py:94:handleHostResolvedSuccess
]
